[2024-05-13T07:59:24.957+0000] {taskinstance.py:1157} INFO - Dependencies all met for dep_context=non-requeueable deps ti=<TaskInstance: Sasrec_model_DAG.model_fit manual__2024-05-13T07:15:32.708775+00:00 [queued]>
[2024-05-13T07:59:24.965+0000] {taskinstance.py:1157} INFO - Dependencies all met for dep_context=requeueable deps ti=<TaskInstance: Sasrec_model_DAG.model_fit manual__2024-05-13T07:15:32.708775+00:00 [queued]>
[2024-05-13T07:59:24.965+0000] {taskinstance.py:1359} INFO - Starting attempt 2 of 2
[2024-05-13T07:59:24.976+0000] {taskinstance.py:1380} INFO - Executing <Task(_PythonDecoratedOperator): model_fit> on 2024-05-13 07:15:32.708775+00:00
[2024-05-13T07:59:24.987+0000] {standard_task_runner.py:57} INFO - Started process 1877 to run task
[2024-05-13T07:59:24.991+0000] {standard_task_runner.py:84} INFO - Running: ['***', 'tasks', 'run', 'Sasrec_model_DAG', 'model_fit', 'manual__2024-05-13T07:15:32.708775+00:00', '--job-id', '12', '--raw', '--subdir', 'DAGS_FOLDER/sasrec_dag.py', '--cfg-path', '/tmp/tmph3klccnw']
[2024-05-13T07:59:24.994+0000] {standard_task_runner.py:85} INFO - Job 12: Subtask model_fit
[2024-05-13T07:59:25.031+0000] {task_command.py:415} INFO - Running <TaskInstance: Sasrec_model_DAG.model_fit manual__2024-05-13T07:15:32.708775+00:00 [running]> on host a7d11f6dcbcd
[2024-05-13T07:59:25.099+0000] {taskinstance.py:1660} INFO - Exporting env vars: AIRFLOW_CTX_DAG_OWNER='***' AIRFLOW_CTX_DAG_ID='Sasrec_model_DAG' AIRFLOW_CTX_TASK_ID='model_fit' AIRFLOW_CTX_EXECUTION_DATE='2024-05-13T07:15:32.708775+00:00' AIRFLOW_CTX_TRY_NUMBER='2' AIRFLOW_CTX_DAG_RUN_ID='manual__2024-05-13T07:15:32.708775+00:00'
[2024-05-13T07:59:25.122+0000] {instantiator.py:21} INFO - Created a temporary directory at /tmp/tmpreh5me_r
[2024-05-13T07:59:25.123+0000] {instantiator.py:76} INFO - Writing /tmp/tmpreh5me_r/_remote_module_non_scriptable.py
[2024-05-13T07:59:25.398+0000] {log.py:232} WARNING - INFO: GPU available: False, used: False
[2024-05-13T07:59:25.397+0000] {rank_zero.py:63} INFO - GPU available: False, used: False
[2024-05-13T07:59:25.398+0000] {log.py:232} WARNING - INFO: TPU available: False, using: 0 TPU cores
[2024-05-13T07:59:25.398+0000] {rank_zero.py:63} INFO - TPU available: False, using: 0 TPU cores
[2024-05-13T07:59:25.398+0000] {log.py:232} WARNING - INFO: IPU available: False, using: 0 IPUs
[2024-05-13T07:59:25.398+0000] {rank_zero.py:63} INFO - IPU available: False, using: 0 IPUs
[2024-05-13T07:59:25.398+0000] {log.py:232} WARNING - INFO: HPU available: False, using: 0 HPUs
[2024-05-13T07:59:25.398+0000] {rank_zero.py:63} INFO - HPU available: False, using: 0 HPUs
[2024-05-13T07:59:25.425+0000] {exceptions.py:175} WARNING - /home/***/.local/lib/python3.10/site-packages/lightning/pytorch/callbacks/model_checkpoint.py:653: Checkpoint directory /opt/***/model_checkpoints exists and is not empty.

[2024-05-13T07:59:25.427+0000] {log.py:232} WARNING - INFO: 
  | Name   | Type             | Params
--------------------------------------------
0 | _model | SasRecModel      | 159 K 
1 | _loss  | CrossEntropyLoss | 0     
--------------------------------------------
159 K     Trainable params
0         Non-trainable params
159 K     Total params
0.637     Total estimated model params size (MB)
[2024-05-13T07:59:25.427+0000] {model_summary.py:94} INFO - 
  | Name   | Type             | Params
--------------------------------------------
0 | _model | SasRecModel      | 159 K 
1 | _loss  | CrossEntropyLoss | 0     
--------------------------------------------
159 K     Trainable params
0         Non-trainable params
159 K     Total params
0.637     Total estimated model params size (MB)
[2024-05-13T07:59:25.435+0000] {logging_mixin.py:151} INFO - Sanity Checking: |          | 0/? [00:00<?, ?it/s]
[2024-05-13T07:59:25.445+0000] {taskinstance.py:1935} ERROR - Task failed with exception
Traceback (most recent call last):
  File "/home/airflow/.local/lib/python3.10/site-packages/airflow/decorators/base.py", line 221, in execute
    return_value = super().execute(context)
  File "/home/airflow/.local/lib/python3.10/site-packages/airflow/operators/python.py", line 192, in execute
    return_value = self.execute_callable()
  File "/home/airflow/.local/lib/python3.10/site-packages/airflow/operators/python.py", line 209, in execute_callable
    return self.python_callable(*self.op_args, **self.op_kwargs)
  File "/opt/airflow/dags/sasrec_dag.py", line 297, in model_fit
    trainer.fit(
  File "/home/airflow/.local/lib/python3.10/site-packages/lightning/pytorch/trainer/trainer.py", line 544, in fit
    call._call_and_handle_interrupt(
  File "/home/airflow/.local/lib/python3.10/site-packages/lightning/pytorch/trainer/call.py", line 44, in _call_and_handle_interrupt
    return trainer_fn(*args, **kwargs)
  File "/home/airflow/.local/lib/python3.10/site-packages/lightning/pytorch/trainer/trainer.py", line 580, in _fit_impl
    self._run(model, ckpt_path=ckpt_path)
  File "/home/airflow/.local/lib/python3.10/site-packages/lightning/pytorch/trainer/trainer.py", line 987, in _run
    results = self._run_stage()
  File "/home/airflow/.local/lib/python3.10/site-packages/lightning/pytorch/trainer/trainer.py", line 1031, in _run_stage
    self._run_sanity_check()
  File "/home/airflow/.local/lib/python3.10/site-packages/lightning/pytorch/trainer/trainer.py", line 1060, in _run_sanity_check
    val_loop.run()
  File "/home/airflow/.local/lib/python3.10/site-packages/lightning/pytorch/loops/utilities.py", line 182, in _decorator
    return loop_run(self, *args, **kwargs)
  File "/home/airflow/.local/lib/python3.10/site-packages/lightning/pytorch/loops/evaluation_loop.py", line 113, in run
    self.reset()
  File "/home/airflow/.local/lib/python3.10/site-packages/lightning/pytorch/loops/evaluation_loop.py", line 231, in reset
    iter(data_fetcher)  # creates the iterator inside the fetcher
  File "/home/airflow/.local/lib/python3.10/site-packages/lightning/pytorch/loops/fetchers.py", line 104, in __iter__
    super().__iter__()
  File "/home/airflow/.local/lib/python3.10/site-packages/lightning/pytorch/loops/fetchers.py", line 51, in __iter__
    self.iterator = iter(self.combined_loader)
  File "/home/airflow/.local/lib/python3.10/site-packages/lightning/pytorch/utilities/combined_loader.py", line 351, in __iter__
    iter(iterator)
  File "/home/airflow/.local/lib/python3.10/site-packages/lightning/pytorch/utilities/combined_loader.py", line 155, in __iter__
    self._load_current_iterator()
  File "/home/airflow/.local/lib/python3.10/site-packages/lightning/pytorch/utilities/combined_loader.py", line 173, in _load_current_iterator
    self.iterators = [iter(self.iterables[self._iterator_idx])]
  File "/home/airflow/.local/lib/python3.10/site-packages/torch/utils/data/dataloader.py", line 435, in __iter__
    return self._get_iterator()
  File "/home/airflow/.local/lib/python3.10/site-packages/torch/utils/data/dataloader.py", line 381, in _get_iterator
    return _MultiProcessingDataLoaderIter(self)
  File "/home/airflow/.local/lib/python3.10/site-packages/torch/utils/data/dataloader.py", line 1034, in __init__
    w.start()
  File "/usr/local/lib/python3.10/multiprocessing/process.py", line 118, in start
    assert not _current_process._config.get('daemon'), \
AssertionError: daemonic processes are not allowed to have children
[2024-05-13T07:59:25.453+0000] {taskinstance.py:1398} INFO - Marking task as FAILED. dag_id=Sasrec_model_DAG, task_id=model_fit, execution_date=20240513T071532, start_date=20240513T075924, end_date=20240513T075925
[2024-05-13T07:59:25.464+0000] {standard_task_runner.py:104} ERROR - Failed to execute job 12 for task model_fit (daemonic processes are not allowed to have children; 1877)
[2024-05-13T07:59:25.482+0000] {local_task_job_runner.py:228} INFO - Task exited with return code 1
[2024-05-13T07:59:25.503+0000] {taskinstance.py:2776} INFO - 0 downstream tasks scheduled from follow-on schedule check
